Workbook
Name Slicer_Area: #N/A
Name Slicer_Area1: #N/A
Name Slicer_Customer_Type: #N/A
Name Slicer_Customer_Type1: #N/A
Name Slicer_Payment_Status: #N/A
Name Slicer_Payment_Status1: #N/A
Name Slicer_Reading_Date1: #N/A

Sheet Project_Index
A1: No. | B1: Student Name | C1: Project Title | D1: Dataset Sheet | E1: Rows | F1: Columns | G1: Status | I1: Data Quality Note
A2: 1 | B2: Aba Muxudiin Ahmed | C2: Student Enrollment Data Analysis Using Excel | D2: 01_Enrollment | E2: 300 | F2: 7 | G2: Ready | I2: Each project dataset now includes 15 additional empty cells in every one of its 7 columns for missing-value cleaning practice.
A3: 2 | B3: Abdikarim Ismail Ali | C3: Customer Purchase & Sales Performance Analysis Using Excel | D3: 02_Sales | E3: 300 | F3: 7 | G3: Ready
A4: 3 | B4: Abdinajib Abdullahi Muse | C4: Employee Attendance Data Analysis Using Excel | D4: 03_Emp_Attendance | E4: 300 | F4: 7 | G4: Ready
A5: 4 | B5: Aisha Mohamed Abdullahi | C5: Restaurant Sales and Customer Analysis Using Excel | D5: 04_Restaurant | E5: 300 | F5: 7 | G5: Ready
A6: 5 | B6: Aniso Ahmed Mohamud | C6: TITLE NOT PROVIDED | E6: 0 | F6: 0 | G6: Project title needed
A7: 6 | B7: Axmed Abduqadir Iman | C7: Electricity Consumption Data Analysis Using Excel | D7: 06_Electricity | E7: 300 | F7: 7 | G7: Ready
A8: 7 | B8: Ayuub Abdullahi Isxaakh | C8: Hospital Patient Data Analysis Using Excel | D8: 07_Hospital | E8: 300 | F8: 7 | G8: Ready
A9: 8 | B9: Cayni Abuukar Maxamuud | C9: Real Estate Property Data Analysis Using Excel | D9: 08_Real_Estate | E9: 300 | F9: 7 | G9: Ready
A10: 9 | B10: Deqo Abdulkhadir Hussein | C10: Student Attendance and Academic Analysis | D10: 09_Academic | E10: 300 | F10: 7 | G10: Ready
A11: 10 | B11: Faadumo Mahamed Yusuf | C11: Internet Usage Data Analysis | D11: 10_Internet | E11: 300 | F11: 7 | G11: Ready
A12: 11 | B12: Fardowso Gamadiid Imaan | C12: Employee Salary Data Analysis Using Excel | D12: 11_Salary | E12: 300 | F12: 7 | G12: Ready
A13: 12 | B13: Fartun Ali Maxamuud | C13: Fuel Consumption and Vehicle Analysis Using Excel | D13: 12_Fuel | E13: 300 | F13: 7 | G13: Ready
A14: 13 | B14: Faysal Mohamed Dahir | C14: Customer Demographic Data Analysis | D14: 13_Demographic | E14: 300 | F14: 7 | G14: Ready
A15: 14 | B15: Hawo Abdi Maxamed | C15: Weather and Temperature Data Analysis | D15: 14_Weather | E15: 300 | F15: 7 | G15: Ready
A16: 15 | B16: Hudeifa Mohamud Ahmed | C16: Monthly Expense and Budget Analysis | D16: 15_Budget | E16: 300 | F16: 7 | G16: Ready
A17: 16 | B17: Ibrahim Abdullahi Farhan | C17: Public Transportation Performance Analysis | D17: 16_Transport | E17: 300 | F17: 7 | G17: Ready
A18: 17 | B18: Miski Mohamed Abdullahi | C18: Hotel Booking and Customer Analysis | D18: 17_Hotel | E18: 300 | F18: 7 | G18: Ready
... A25: 24 | B25: Sucdi Yasin Husein | C25: Job Recruitment and Applicant Data Analysis | D25: 24_Recruitment | E25: 300 | F25: 7 | G25: Ready

Sheet Data_clean
A1: Meter_ID | B1: Reading_Date | C1: Area | D1: Customer_Type | E1: Units_kWh | F1: Tariff_per_kWh | G1: Payment_Status | H1: Total Revenue
A2: MTR0003 | B2: 45867 | C2: Mogadishu | D2: Commercial | E2: 1955.8 | F2: 0.212 | G2: Paid | H2: =Table2[[#This Row],[Units_kWh]]*Table2[[#This Row],[Tariff_per_kWh]] -> 414.6296
A3: MTR0004 | B3: 45699 | C3: Baidoa | D3: Commercial | E3: 1900.5 | F3: 0.225 | G3: Paid | H3: =Table2[[#This Row],[Units_kWh]]*Table2[[#This Row],[Tariff_per_kWh]] -> 427.6125
A4: MTR0005 | B4: 45717 | C4: Kismayo | D4: Commercial | E4: 1713.4 | F4: 0.216 | G4: Paid | H4: =Table2[[#This Row],[Units_kWh]]*Table2[[#This Row],[Tariff_per_kWh]] -> 370.0944
A5: MTR0014 | B5: 46153 | C5: Mogadishu | D5: Commercial | E5: 0 | F5: 0.228 | G5: Pending | H5: =Table2[[#This Row],[Units_kWh]]*Table2[[#This Row],[Tariff_per_kWh]] -> 0
A6: MTR0015 | B6: 45822 | C6: Baidoa | D6: Commercial | E6: 2125 | F6: 0.215 | G6: non_pay | H6: =Table2[[#This Row],[Units_kWh]]*Table2[[#This Row],[Tariff_per_kWh]] -> 456.875
A7: MTR0017 | B7: 46206 | C7: Baidoa | D7: Commercial | E7: 850.9 | F7: 0.216 | G7: Paid | H7: =Table2[[#This Row],[Units_kWh]]*Table2[[#This Row],[Tariff_per_kWh]] -> 183.7944
A8: MTR0020 | B8: 45964 | C8: Mogadishu | D8: Commercial | E8: 1492.5 | F8: 0.223 | G8: Paid | H8: =Table2[[#This Row],[Units_kWh]]*Table2[[#This Row],[Tariff_per_kWh]] -> 332.8275
A9: MTR0023 | B9: 45747 | C9: Mogadishu | D9: Commercial | E9: 1294.1 | F9: 0.209 | G9: Paid | H9: =Table2[[#This Row],[Units_kWh]]*Table2[[#This Row],[Tariff_per_kWh]] -> 270.4669
A10: MTR0028 | B10: 46076 | C10: Mogadishu | D10: Commercial | E10: 2003.7 | F10: 0.214 | G10: Paid | H10: =Table2[[#This Row],[Units_kWh]]*Table2[[#This Row],[Tariff_per_kWh]] -> 428.7918
A11: MTR0029 | B11: 46027 | C11: Bosaso | D11: Commercial | E11: 693.1 | F11: 0.221 | G11: Paid | H11: =Table2[[#This Row],[Units_kWh]]*Table2[[#This Row],[Tariff_per_kWh]] -> 153.1751
A12: MTR0036 | B12: 45934 | C12: Bosaso | D12: Commercial | E12: 2118.5 | F12: 0.221 | G12: Paid | H12: =Table2[[#This Row],[Units_kWh]]*Table2[[#This Row],[Tariff_per_kWh]] -> 468.1885
A13: MTR0046 | B13: 46065 | C13: Garowe | D13: Commercial | E13: 1782 | F13: 0.23 | G13: pending | H13: =Table2[[#This Row],[Units_kWh]]*Table2[[#This Row],[Tariff_per_kWh]] -> 409.86
... A301: MTR0300 | B301: 45934 | C301: Bosaso | D301: non_customer | E301: 4843.1 | F301: 0.253 | G301: Paid | H301: =Table2[[#This Row],[Units_kWh]]*Table2[[#This Row],[Tariff_per_kWh]] -> 1225.3043

Sheet 06_Electricity
A1: Meter_ID | B1: Reading_Date | C1: Area | D1: Customer_Type | E1: Units_kWh | F1: Tariff_per_kWh | G1: Payment_Status
A2: MTR0144 | B2: 45841 | C2: Garowe | D2: Residential | E2: 189.1 | F2: 0.184 | G2: Pending
A3: MTR0151 | B3: 46085 | C3: Kismayo | D3: Residential | E3: 329.7 | F3: 0.178 | G3: Paid
A4: MTR0142 | B4: 46028 | C4: Hargeisa | D4: Commercial | F4: 0.213 | G4: Paid
A5: MTR0038 | B5: 45962 | C5: Mogadishu | D5: Unknown | E5: 528.4 | F5: 0.179 | G5: Paid
A6: MTR0060 | B6: 45839 | C6: Kismayo | E6: 163 | F6: 0.185 | G6: Paid
A7: MTR0190 | B7: 45775 | C7: Bosaso | D7: Industrial | E7: 4182.5 | F7: 0.26 | G7: Paid
A8: MTR0180 | B8: 45831 | C8: Bosaso | D8: Residential | E8: 493.3 | F8: 0.184 | G8: Pending
A9: MTR0229 | B9: 45708 | C9: Mogadishu | E9: 392.9 | F9: 0.187 | G9: Paid
A10: MTR0219 | B10: 45814 | D10: Residential | E10: 540.8 | F10: 0.182 | G10: Paid
A11: MTR0278 | B11: 46007 | C11: Mogadishu | D11: Residential | E11: 563.3 | F11: 0.183 | G11: Paid
A12: MTR0071 | B12: 45950 | C12: Mogadishu | D12: Residential | E12: 285.2 | F12: 0.178 | G12: Paid
A13: MTR0014 | B13: 46153 | C13: Mogadishu | D13: Commercial | F13: 0.228 | G13: Pending
A14: MTR0196 | B14: 45718 | C14: Baidoa | D14: Residential | E14: 10022 | F14: 0.187 | G14: Paid
A15: MTR0139 | B15: 45668 | C15: Mogadishu | D15: Residential | E15: 475 | F15: 0.176 | G15: Paid
A16: MTR0052 | B16: 46048 | C16: Mogadishu | D16: Residential | E16: 464.8 | F16: 0.188 | G16: Paid
A17: MTR0128 | B17: 46015 | C17: Kismayo | D17: Residential | E17: 566.8 | F17: 0.187 | G17: Paid
A18: MTR0212 | B18: 45897 | C18: Mogadishu | D18: Residential | E18: 359.6 | F18: 0.183 | G18: Paid
A19: MTR0030 | B19: 46027 | C19: Bosaso | D19: Commercial | E19: 693.1 | F19: 0.221 | G19: Paid
A20: MTR0095 | B20: 45691 | C20: Baidoa | D20: Commercial | E20: 578.2 | F20: 0.229 | G20: Paid
A21: MTR0114 | B21: 45958 | C21: Mogadishu | D21: Residential | E21: 548 | F21: 0.181 | G21: Paid
A22: MTR0223 | B22: 45841 | C22: Mogadishu | D22: Commercial | E22: 545.5 | F22: 0.226 | G22: Paid
A23: MTR0174 | B23: 45873 | C23: Bosaso | D23: Residential | E23: 273.3 | F23: 0.176
A24: MTR0111 | B24: 45943 | C24: Garowe | D24: Residential | E24: 458.8 | F24: 0.172 | G24: Paid
A25: MTR0175 | C25: Garowe | D25: Residential | E25: 427.8 | F25: 0.171 | G25: Paid
A26: MTR0104 | B26: 45935 | C26: Mogadishu | D26: Residential | E26: 447.4 | F26: 0.18 | G26: Paid
A27: MTR0153 | B27: 45856 | C27: Mogadishu | E27: 2133.9 | F27: 0.225 | G27: Paid
A28: MTR0109 | B28: 45774 | C28: Bosaso | D28: Residential | E28: 145.2 | F28: 0.184 | G28: Paid
A29: MTR0108 | B29: 46208 | C29: Garowe | D29: Commercial | E29: 1549.2 | F29: 0.21 | G29: Pending
A30: MTR0025 | C30: Hargeisa | D30: Residential | E30: 585.2 | F30: 0.174 | G30: Pending
A31: MTR0033 | B31: 46209 | C31: Baidoa | D31: Residential | E31: 508.8 | F31: 0.185 | G31: Paid
A32: MTR0018 | B32: 45884 | C32: Garowe | D32: Residential | E32: 86 | F32: 0.172 | G32: Paid
A33: MTR0120 | B33: 45659 | C33: Mogadishu | D33: Industrial | E33: 2743.3 | F33: 0.259 | G33: pending
A34: MTR0218 | B34: 46207 | C34: Mogadishu | D34: Commercial | E34: 1522.7 | F34: 0.223 | G34: Pending
A35: MTR0231 | B35: 46078 | C35: Mogadishu | D35: Commercial | E35: 539 | F35: 0.215 | G35: Paid
A36: MTR0227 | B36: 45965 | C36: Hargeisa | D36: Commercial | E36: 2109.5 | F36: 0.229 | G36: Pending
B37: 45991 | C37: Hargeisa | D37: Residential | E37: 175.7 | F37: Unknown | G37: Paid
A38: MTR0285 | B38: 46196 | C38: Bosaso | D38: Residential | E38: 308.1 | F38: 0.188 | G38: Overdue
A39: MTR0244 | B39: 45828 | C39: Baidoa | D39: Commercial | E39: 2009.8 | F39: 0.231 | G39: Paid
A40: MTR0039 | B40: 45986 | C40: Hargeisa | D40: Residential | E40: 184.8 | F40: 0.188 | G40: Paid
...

Sheet PivotAreaByRevenue
A3: Row Labels | B3: Sum of Units_kWh | C3: Sum of Total Revenue
A4: Baidoa | B4: 30969.4 | C4: 6169.256
A5: Bosaso | B5: 29745.6 | C5: 6648.621
A6: Garowe | B6: 39842.1 | C6: 9052.091
A7: Hargeisa | B7: 51334.7 | C7: 11401.148
A8: Kismayo | B8: 27135 | C8: 5479.202
A9: Mogadishu | B9: 114749.9 | C9: 27713.966
A10: Grand Total | B10: 293776.7 | C10: 66464.284

Sheet PovitCustomerType
A3: Row Labels | B3: Sum of Total Revenue | C3: Sum of Units_kWh
A4: Commercial | B4: 20852.167 | C4: 97104.3
A5: Industrial | B5: 23465.786 | C5: 93113.7
A6: Residential | B6: 22146.331 | C6: 103558.7
A7: Grand Total | B7: 66464.284 | C7: 293776.7

Sheet PovitPayment
A3: Row Labels | B3: Sum of Total Revenue | C3: Count of Meter_ID
A4: Overdue | B4: 9148.02 | C4: 36
A5: Paid | B5: 44746.027 | C5: 192
A6: Pending | B6: 12570.237 | C6: 72
A7: Grand Total | B7: 66464.284 | C7: 300

Sheet PivotReading_date
A3: Row Labels | B3: Sum of Units_kWh
A4: Jan | B4: 45407
A5: Feb | B5: 37928.9
A6: Mar | B6: 37535.6
A7: Apr | B7: 24437.8
A8: May | B8: 10392.6
A9: Jun | B9: 31732.3
A10: Jul | B10: 34884.6
A11: Aug | B11: 10526.6
A12: Sep | B12: 9953.5
A13: Oct | B13: 17197.1
A14: Nov | B14: 17302.8
A15: Dec | B15: 16477.9
A16: Grand Total | B16: 293776.7

Sheet PovitConsumptionbyArea
A3: Row Labels | B3: Sum of Units_kWh
A4: Baidoa | B4: 30969.4
A5: Bosaso | B5: 29745.6
A6: Garowe | B6: 39842.1
A7: Hargeisa | B7: 51334.7
A8: Kismayo | B8: 27135
A9: Mogadishu | B9: 114749.9
A10: Grand Total | B10: 293776.7

Sheet Dashboard
A3: DASHBOARD ELECTRICITY CONSUMPTION
A9: SLICERS | D9: Total Consumption (kWh) | G9: Total Revenue | J9: Average Consumption | M9: Number of Customers / Meters | P9: Paid Customers | S9: Pending Customers | V9: Payment Rate % | Y9: Average Revenue per Customer
D10: =GETPIVOTDATA("Units_kWh",'pivot table'!$N$33) -> 974.80567 | G10: =GETPIVOTDATA("Sum of Total Revenue",'pivot table'!$A$2) -> 55653.579 | J10: =GETPIVOTDATA("Units_kWh",'pivot table'!$N$33) -> 974.80567 | M10: =GETPIVOTDATA("Count of Customer_Type",'pivot table'!$B$32) -> 300 | P10: =GETPIVOTDATA("Count of Customer_Type",'pivot table'!$B$32,"Payment_Status","Paid") -> 190 | S10: =GETPIVOTDATA("Count of Customer_Type",'pivot table'!$B$32,"Payment_Status","Pending") -> 54 | V10: =GETPIVOTDATA("Count of Customer_Type",'pivot table'!$B$32,"Payment_Status","Paid")/GETPIVOTDATA("Count of Customer_Type",'pivot table'!$B$32) -> 0.63333333 | Y10: =GETPIVOTDATA("Average of Total Revenue",'pivot table'!$B$32) -> 185.51193
D12: Consumption By Area Chart | P12: Revenue By Area Chart
D29: Customer Type Chart | P29: Payment Status Chart
D46: Reading_Date Chart

Sheet Analysis
A1: Analysis
A6: DATA BLANKS | H6: Area | Q6: CUSTOMER TYPE
A8: 1 | B8: Meter Id | C8: =COUNTBLANK('06_Electricity'!A2:A301) -> 15 | I8: Area
A9: 2 | B9: Reading Date | C9: =COUNTBLANK('06_Electricity'!B2:B301) -> 15 | H9: 1 | I9: Baidoa | J9: =COUNTIF('06_Electricity'!C2:C301,"Baidoa") -> 31 | R9: Commercial | S9: =COUNTIF('06_Electricity'!D2:D301,"Commercial") -> 75
A10: 3 | B10: Customer Type | C10: =COUNTBLANK('06_Electricity'!C2:C301) -> 15 | H10: 2 | I10: Bosaso | J10: =COUNTIF('06_Electricity'!C2:C301,"Bosaso") -> 38 | R10: Residential | S10: =COUNTIF('06_Electricity'!D2:D301,"Residential") -> 187
A11: 4 | B11: Units_KWh | C11: =COUNTBLANK('06_Electricity'!D2:D301) -> 16 | H11: 3 | I11: Garowe | J11: =COUNTIF('06_Electricity'!C2:C301,"Garowe") -> 32 | R11: Industrial | S11: =COUNTIF('06_Electricity'!D2:D301,"Industrial") -> 20
A12: 5 | B12: Tariff_per_kWh | C12: =COUNTBLANK('06_Electricity'!F2:F301) -> 16 | H12: 4 | I12: Hargeisa | J12: =COUNTIF('06_Electricity'!C2:C301,"Hargeisa") -> 58 | R12: Unknown | S12: =COUNTIF('06_Electricity'!D2:D301,"Unknown") -> 2
A13: 6 | B13: Payment status | C13: =COUNTBLANK('06_Electricity'!F2:F301) -> 16 | H13: 5 | I13: Kismayo | J13: =COUNTIF('06_Electricity'!C2:C301,"Kismayo") -> 28 | R13: blank | S13: =COUNTIF('06_Electricity'!D2:D301,"") -> 16
A14: 7 | B14: Area | C14: =COUNTBLANK('06_Electricity'!C2:C301) -> 15 | H14: 6 | I14: Mogadishu | J14: =COUNTIF('06_Electricity'!C2:C301,"Mogadishu") -> 98 | Q14: TOTAL | S14: =SUM(S9:S13) -> 300
H15: 7 | I15: blanks | J15: =COUNTIF('06_Electricity'!C2:C301,"") -> 15
A16: TOTAL | C16: =SUM(C8:C14) -> 108 | H16: TOTAL | J16: =SUM(J9:J15) -> 300
A21: Area Units_kWh | H21: Tariff_per_kWh | Q21: Area Revenue
B23: area | C23: Units_kWh | I23: Area | J23: Tariff_per_kWh
B24: Baidoa | C24: =SUMIF('06_Electricity'!C2:C301,"Baidoa",'06_Electricity'!E2:E301) -> 30969.4 | I24: Baidoa | J24: =SUMIF('06_Electricity'!C2:C301,"Baidoa",'06_Electricity'!F2:F301) -> 5.779 | R24: Baidoa | S24: =SUMIF(Data_clean!C2:C301,"Baidoa",Data_clean!H2:H301) -> 5807.8971
B25: Bosaso | C25: =SUMIF('06_Electricity'!C2:C301,"Bosaso",'06_Electricity'!E2:E301) -> 29487.6 | I25: Bosaso | J25: =SUMIF('06_Electricity'!C2:C301,"Bosaso",'06_Electricity'!F2:F301) -> 7.356 | R25: Bosaso | S25: =SUMIF(Data_clean!C2:C301,"Bosaso",Data_clean!H2:H301) -> 6562.1676
B26: Garowe | C26: =SUMIF('06_Electricity'!C2:C301,"Garowe",'06_Electricity'!E2:E301) -> 39842.1 | I26: Garowe | J26: =SUMIF('06_Electricity'!C2:C301,"Garowe",'06_Electricity'!F2:F301) -> 5.696 | R26: Garowe | S26: =SUMIF(Data_clean!C2:C301,"Garowe",Data_clean!H2:H301) -> 8735.5064
B27: Hargeisa | C27: =SUMIF('06_Electricity'!C2:C301,"Hargeisa",'06_Electricity'!E2:E301) -> 51167.7 | I27: Hargeisa | J27: =SUMIF('06_Electricity'!C2:C301,"Hargeisa",'06_Electricity'!F2:F301) -> 0.502 | R27: Hargeisa | S27: =SUMIF(Data_clean!C2:C301,"Hargeisa",Data_clean!H2:H301) -> 5023.102
B28: Kismayo | C28: =SUMIF('06_Electricity'!C2:C301,"Kismayo",'06_Electricity'!E2:E301) -> 26954 | I28: Kismayo | J28: =SUMIF('06_Electricity'!C2:C301,"Kismayo",'06_Electricity'!F2:F301) -> 4.764 | R28: Kismayo | S28: =SUMIF(Data_clean!C2:C301,"Kismayo",Data_clean!H2:H301) -> 5058.1601
B29: Mogadishu | C29: =SUMIF('06_Electricity'!C2:C301,"Mogadishu",'06_Electricity'!E2:E301) -> 100110.4 | I29: Mogadishu | J29: =SUMIF('06_Electricity'!C2:C301,"Mogadishu",'06_Electricity'!F2:F301) -> 41.232 | R29: Mogadishu | S29: =SUMIF(Data_clean!C2:C301,"Mogadishu",Data_clean!H2:H301) -> 21422.383
B30: blanks | C30: =SUMIF('06_Electricity'!C2:C301,"",'06_Electricity'!E2:E301) -> 13910.5 | I30: blanks | J30: =SUMIF('06_Electricity'!C2:C301,"",'06_Electricity'!F2:F301) -> 2.838 | R30: blanks | S30: =SUMIF(Data_clean!C2:C301,"non_area",Data_clean!H2:H301) -> 3044.3631
A31: TOTAL | C31: =SUM(C24:C30) -> 292441.7 | H31: total | J31: =SUM(J24:J30) -> 68.167 | Q31: TOTAL | S31: =SUM(S24:S30) -> 55653.579
A34: Total revenue

Sheet pivot table
A2: Row Labels | B2: Sum of Units_kWh | C2: Sum of Total Revenue | F2: Row Labels | G2: Sum of Total Revenue | H2: Sum of Units_kWh
A3: Baidoa | B3: 30969.4 | C3: 5807.8971 | F3: Commercial | G3: 19009.893 | H3: 96154.6
A4: Bosaso | B4: 29487.6 | C4: 6562.1676 | F4: Industrial | G4: 23422.939 | H4: 92410.3
A5: Garowe | B5: 39842.1 | C5: 8735.5064 | F5: non_customer | G5: 5051.0897 | H5: 21777
A6: Hargeisa | B6: 51167.7 | C6: 5023.102 | F6: Residential | G6: 8169.6568 | H6: 82099.8
A7: Kismayo | B7: 26954 | C7: 5058.1601 | F7: (blank)
A8: Mogadishu | B8: 100110.4 | C8: 21422.383 | F8: Grand Total | G8: 55653.579 | H8: 292441.7
A9: non_area | B9: 13910.5 | C9: 3044.3631
A10: (blank)
A11: Grand Total | B11: 292441.7 | C11: 55653.579
B32: Row Labels | C32: Average of Total Revenue | D32: Count of Customer_Type
B33: non_pay | C33: 241.32545 | D33: 20 | N33: Row Labels | O33: Average of Units_kWh
B34: Overdue | C34: 243.77101 | D34: 36 | N34: Baidoa | O34: 999.0129
B35: Paid | C35: 180.71923 | D35: 190 | N35: Bosaso | O35: 775.98947
B36: Pending | C36: 142.86409 | D36: 54 | N36: Garowe | O36: 1245.0656
B37: (blank) | N37: Hargeisa | O37: 882.20172
B38: Grand Total | C38: 185.51193 | D38: 300 | N38: Kismayo | O38: 962.64286
N39: Mogadishu | O39: 1021.5347
N40: non_area | O40: 927.36667
N41: (blank)
N42: Grand Total | O42: 974.80567
